<?xml version="1.0" ?>
<robot name="partnet_21f3c0d4604587b4da5feafe6f1c8fc">
	<link name="base"/>
	<link name="link_0">
		<visual name="cabinet_door_surface-10">
			<origin xyz="-0.6864633732831515 -0.6367499828338625 -0.4538667972764191"/>
			<geometry>
				<mesh filename="package://objects_description/45420/textured_objs/original-31.obj"/>
			</geometry>
		</visual>
		<visual name="handle-11">
			<origin xyz="-0.6864633732831515 -0.6367499828338625 -0.4538667972764191"/>
			<geometry>
				<mesh filename="package://objects_description/45420/textured_objs/original-33.obj"/>
			</geometry>
		</visual>
		<visual name="handle-11">
			<origin xyz="-0.6864633732831515 -0.6367499828338625 -0.4538667972764191"/>
			<geometry>
				<mesh filename="package://objects_description/45420/textured_objs/original-35.obj"/>
			</geometry>
		</visual>
		<visual name="handle-11">
			<origin xyz="-0.6864633732831515 -0.6367499828338625 -0.4538667972764191"/>
			<geometry>
				<mesh filename="package://objects_description/45420/textured_objs/original-34.obj"/>
			</geometry>
		</visual>
		<collision>
			<origin xyz="-0.6864633732831515 -0.6367499828338625 -0.4538667972764191"/>
			<geometry>
				<mesh filename="package://objects_description/45420/textured_objs/original-31.obj"/>
			</geometry>
		</collision>
		<collision>
			<origin xyz="-0.6864633732831515 -0.6367499828338625 -0.4538667972764191"/>
			<geometry>
				<mesh filename="package://objects_description/45420/textured_objs/original-33.obj"/>
			</geometry>
		</collision>
		<collision>
			<origin xyz="-0.6864633732831515 -0.6367499828338625 -0.4538667972764191"/>
			<geometry>
				<mesh filename="package://objects_description/45420/textured_objs/original-35.obj"/>
			</geometry>
		</collision>
		<collision>
			<origin xyz="-0.6864633732831515 -0.6367499828338625 -0.4538667972764191"/>
			<geometry>
				<mesh filename="package://objects_description/45420/textured_objs/original-34.obj"/>
			</geometry>
		</collision>
	</link>
	<joint name="joint_0" type="revolute">
		<origin xyz="0.6864633732831515 0.6367499828338625 0.4538667972764191"/>
		<axis xyz="0 1 0"/>
		<child link="link_0"/>
		<parent link="link_2"/>
		<limit lower="0.0" upper="1.6022122533307945"/>
	</joint>
	<link name="link_1">
		<visual name="cabinet_door_surface-8">
			<origin xyz="0.6441316048736573 0.48602798581123374 -0.4534843984788899"/>
			<geometry>
				<mesh filename="package://objects_description/45420/textured_objs/original-25.obj"/>
			</geometry>
		</visual>
		<visual name="handle-9">
			<origin xyz="0.6441316048736573 0.48602798581123374 -0.4534843984788899"/>
			<geometry>
				<mesh filename="package://objects_description/45420/textured_objs/original-27.obj"/>
			</geometry>
		</visual>
		<visual name="handle-9">
			<origin xyz="0.6441316048736573 0.48602798581123374 -0.4534843984788899"/>
			<geometry>
				<mesh filename="package://objects_description/45420/textured_objs/original-29.obj"/>
			</geometry>
		</visual>
		<visual name="handle-9">
			<origin xyz="0.6441316048736573 0.48602798581123374 -0.4534843984788899"/>
			<geometry>
				<mesh filename="package://objects_description/45420/textured_objs/original-28.obj"/>
			</geometry>
		</visual>
		<collision>
			<origin xyz="0.6441316048736573 0.48602798581123374 -0.4534843984788899"/>
			<geometry>
				<mesh filename="package://objects_description/45420/textured_objs/original-25.obj"/>
			</geometry>
		</collision>
		<collision>
			<origin xyz="0.6441316048736573 0.48602798581123374 -0.4534843984788899"/>
			<geometry>
				<mesh filename="package://objects_description/45420/textured_objs/original-27.obj"/>
			</geometry>
		</collision>
		<collision>
			<origin xyz="0.6441316048736573 0.48602798581123374 -0.4534843984788899"/>
			<geometry>
				<mesh filename="package://objects_description/45420/textured_objs/original-29.obj"/>
			</geometry>
		</collision>
		<collision>
			<origin xyz="0.6441316048736573 0.48602798581123374 -0.4534843984788899"/>
			<geometry>
				<mesh filename="package://objects_description/45420/textured_objs/original-28.obj"/>
			</geometry>
		</collision>
	</link>
	<joint name="joint_1" type="revolute">
		<origin xyz="-0.6441316048736573 -0.48602798581123374 0.4534843984788899"/>
		<axis xyz="0 -0.9999999999999999 0"/>
		<child link="link_1"/>
		<parent link="link_2"/>
		<limit lower="0.0" upper="1.6022122533307945"/>
	</joint>
	<link name="link_2">
		<visual name="shelf-4">
			<origin xyz="0 0 0"/>
			<geometry>
				<mesh filename="package://objects_description/45420/textured_objs/original-2.obj"/>
			</geometry>
		</visual>
		<visual name="shelf-5">
			<origin xyz="0 0 0"/>
			<geometry>
				<mesh filename="package://objects_description/45420/textured_objs/original-23.obj"/>
			</geometry>
		</visual>
		<visual name="frame_vertical_bar-22">
			<origin xyz="0 0 0"/>
			<geometry>
				<mesh filename="package://objects_description/45420/textured_objs/original-4.obj"/>
			</geometry>
		</visual>
		<visual name="frame_vertical_bar-23">
			<origin xyz="0 0 0"/>
			<geometry>
				<mesh filename="package://objects_description/45420/textured_objs/original-18.obj"/>
			</geometry>
		</visual>
		<visual name="frame_vertical_bar-24">
			<origin xyz="0 0 0"/>
			<geometry>
				<mesh filename="package://objects_description/45420/textured_objs/original-8.obj"/>
			</geometry>
		</visual>
		<visual name="frame_horizontal_bar-25">
			<origin xyz="0 0 0"/>
			<geometry>
				<mesh filename="package://objects_description/45420/textured_objs/original-9.obj"/>
			</geometry>
		</visual>
		<visual name="frame_horizontal_bar-26">
			<origin xyz="0 0 0"/>
			<geometry>
				<mesh filename="package://objects_description/45420/textured_objs/original-7.obj"/>
			</geometry>
		</visual>
		<visual name="back_panel-29">
			<origin xyz="0 0 0"/>
			<geometry>
				<mesh filename="package://objects_description/45420/textured_objs/original-6.obj"/>
			</geometry>
		</visual>
		<visual name="bottom_panel-30">
			<origin xyz="0 0 0"/>
			<geometry>
				<mesh filename="package://objects_description/45420/textured_objs/original-3.obj"/>
			</geometry>
		</visual>
		<visual name="vertical_side_panel-31">
			<origin xyz="0 0 0"/>
			<geometry>
				<mesh filename="package://objects_description/45420/textured_objs/original-12.obj"/>
			</geometry>
		</visual>
		<visual name="vertical_side_panel-31">
			<origin xyz="0 0 0"/>
			<geometry>
				<mesh filename="package://objects_description/45420/textured_objs/original-11.obj"/>
			</geometry>
		</visual>
		<visual name="vertical_side_panel-32">
			<origin xyz="0 0 0"/>
			<geometry>
				<mesh filename="package://objects_description/45420/textured_objs/original-16.obj"/>
			</geometry>
		</visual>
		<visual name="vertical_side_panel-32">
			<origin xyz="0 0 0"/>
			<geometry>
				<mesh filename="package://objects_description/45420/textured_objs/original-15.obj"/>
			</geometry>
		</visual>
		<visual name="frame_horizontal_bar-33">
			<origin xyz="0 0 0"/>
			<geometry>
				<mesh filename="package://objects_description/45420/textured_objs/original-22.obj"/>
			</geometry>
		</visual>
		<visual name="frame_horizontal_bar-34">
			<origin xyz="0 0 0"/>
			<geometry>
				<mesh filename="package://objects_description/45420/textured_objs/original-21.obj"/>
			</geometry>
		</visual>
		<visual name="other_leaf-36">
			<origin xyz="0 0 0"/>
			<geometry>
				<mesh filename="package://objects_description/45420/textured_objs/original-36.obj"/>
			</geometry>
		</visual>
		<visual name="frame_horizontal_bar-38">
			<origin xyz="0 0 0"/>
			<geometry>
				<mesh filename="package://objects_description/45420/textured_objs/original-5.obj"/>
			</geometry>
		</visual>
		<visual name="base_side_panel-13">
			<origin xyz="0 0 0"/>
			<geometry>
				<mesh filename="package://objects_description/45420/textured_objs/original-19.obj"/>
			</geometry>
		</visual>
		<visual name="base_side_panel-14">
			<origin xyz="0 0 0"/>
			<geometry>
				<mesh filename="package://objects_description/45420/textured_objs/original-13.obj"/>
			</geometry>
		</visual>
		<visual name="base_side_panel-15">
			<origin xyz="0 0 0"/>
			<geometry>
				<mesh filename="package://objects_description/45420/textured_objs/original-20.obj"/>
			</geometry>
		</visual>
		<visual name="base_side_panel-16">
			<origin xyz="0 0 0"/>
			<geometry>
				<mesh filename="package://objects_description/45420/textured_objs/original-17.obj"/>
			</geometry>
		</visual>
		<collision>
			<origin xyz="0 0 0"/>
			<geometry>
				<mesh filename="package://objects_description/45420/textured_objs/original-2.obj"/>
			</geometry>
		</collision>
		<collision>
			<origin xyz="0 0 0"/>
			<geometry>
				<mesh filename="package://objects_description/45420/textured_objs/original-23.obj"/>
			</geometry>
		</collision>
		<collision>
			<origin xyz="0 0 0"/>
			<geometry>
				<mesh filename="package://objects_description/45420/textured_objs/original-4.obj"/>
			</geometry>
		</collision>
		<collision>
			<origin xyz="0 0 0"/>
			<geometry>
				<mesh filename="package://objects_description/45420/textured_objs/original-18.obj"/>
			</geometry>
		</collision>
		<collision>
			<origin xyz="0 0 0"/>
			<geometry>
				<mesh filename="package://objects_description/45420/textured_objs/original-8.obj"/>
			</geometry>
		</collision>
		<collision>
			<origin xyz="0 0 0"/>
			<geometry>
				<mesh filename="package://objects_description/45420/textured_objs/original-9.obj"/>
			</geometry>
		</collision>
		<collision>
			<origin xyz="0 0 0"/>
			<geometry>
				<mesh filename="package://objects_description/45420/textured_objs/original-7.obj"/>
			</geometry>
		</collision>
		<collision>
			<origin xyz="0 0 0"/>
			<geometry>
				<mesh filename="package://objects_description/45420/textured_objs/original-6.obj"/>
			</geometry>
		</collision>
		<collision>
			<origin xyz="0 0 0"/>
			<geometry>
				<mesh filename="package://objects_description/45420/textured_objs/original-3.obj"/>
			</geometry>
		</collision>
		<collision>
			<origin xyz="0 0 0"/>
			<geometry>
				<mesh filename="package://objects_description/45420/textured_objs/original-12.obj"/>
			</geometry>
		</collision>
		<collision>
			<origin xyz="0 0 0"/>
			<geometry>
				<mesh filename="package://objects_description/45420/textured_objs/original-11.obj"/>
			</geometry>
		</collision>
		<collision>
			<origin xyz="0 0 0"/>
			<geometry>
				<mesh filename="package://objects_description/45420/textured_objs/original-16.obj"/>
			</geometry>
		</collision>
		<collision>
			<origin xyz="0 0 0"/>
			<geometry>
				<mesh filename="package://objects_description/45420/textured_objs/original-15.obj"/>
			</geometry>
		</collision>
		<collision>
			<origin xyz="0 0 0"/>
			<geometry>
				<mesh filename="package://objects_description/45420/textured_objs/original-22.obj"/>
			</geometry>
		</collision>
		<collision>
			<origin xyz="0 0 0"/>
			<geometry>
				<mesh filename="package://objects_description/45420/textured_objs/original-21.obj"/>
			</geometry>
		</collision>
		<collision>
			<origin xyz="0 0 0"/>
			<geometry>
				<mesh filename="package://objects_description/45420/textured_objs/original-36.obj"/>
			</geometry>
		</collision>
		<collision>
			<origin xyz="0 0 0"/>
			<geometry>
				<mesh filename="package://objects_description/45420/textured_objs/original-5.obj"/>
			</geometry>
		</collision>
		<collision>
			<origin xyz="0 0 0"/>
			<geometry>
				<mesh filename="package://objects_description/45420/textured_objs/original-19.obj"/>
			</geometry>
		</collision>
		<collision>
			<origin xyz="0 0 0"/>
			<geometry>
				<mesh filename="package://objects_description/45420/textured_objs/original-13.obj"/>
			</geometry>
		</collision>
		<collision>
			<origin xyz="0 0 0"/>
			<geometry>
				<mesh filename="package://objects_description/45420/textured_objs/original-20.obj"/>
			</geometry>
		</collision>
		<collision>
			<origin xyz="0 0 0"/>
			<geometry>
				<mesh filename="package://objects_description/45420/textured_objs/original-17.obj"/>
			</geometry>
		</collision>
	</link>
	<joint name="joint_2" type="fixed">
		<origin rpy="1.570796326794897 0 -1.570796326794897" xyz="0 0 0"/>
		<child link="link_2"/>
		<parent link="base"/>
	</joint>
</robot>
